{"timestamp":"2025-10-29T11:55:45.002960","level":"info","event":"DAG bundles loaded: dags-folder","logger":"airflow.dag_processing.bundles.manager.DagBundlesManager"}
{"timestamp":"2025-10-29T11:55:45.004188","level":"info","event":"Filling up the DagBag from /opt/airflow/dags/Airflow.py","logger":"airflow.models.dagbag.DagBag"}
{"timestamp":"2025-10-29T11:55:45.085272","level":"info","event":"Tmp dir root location: /tmp","logger":"airflow.task.hooks.airflow.providers.standard.hooks.subprocess.SubprocessHook"}
{"timestamp":"2025-10-29T11:55:45.086754","level":"info","event":"Running command: ['/usr/bin/bash', '-c', 'python3 /opt/airflow/scripts/ARPEGE.py']","logger":"airflow.task.hooks.airflow.providers.standard.hooks.subprocess.SubprocessHook"}
{"timestamp":"2025-10-29T11:55:45.106318","level":"info","event":"Output:","logger":"airflow.task.hooks.airflow.providers.standard.hooks.subprocess.SubprocessHook"}
{"timestamp":"2025-10-29T11:55:49.284697","level":"info","event":"[ INFO ] Checking for files to with more than 7 past days data","logger":"airflow.task.hooks.airflow.providers.standard.hooks.subprocess.SubprocessHook"}
{"timestamp":"2025-10-29T11:55:52.200736","level":"info","event":"[ INFO ] Checking for files to with more than 7 past days data","logger":"airflow.task.hooks.airflow.providers.standard.hooks.subprocess.SubprocessHook"}
{"timestamp":"2025-10-29T11:55:55.009742","level":"info","event":"[ INFO ] Checking for files to with more than 7 past days data","logger":"airflow.task.hooks.airflow.providers.standard.hooks.subprocess.SubprocessHook"}
{"timestamp":"2025-10-29T11:55:57.915453","level":"info","event":"[ INFO ] Checking for files to with more than 7 past days data","logger":"airflow.task.hooks.airflow.providers.standard.hooks.subprocess.SubprocessHook"}
{"timestamp":"2025-10-29T11:56:00.036176","level":"info","event":"üîÑ Descargando datos de http://host.docker.internal:8081/v1/forecast ...","logger":"airflow.task.hooks.airflow.providers.standard.hooks.subprocess.SubprocessHook"}
{"timestamp":"2025-10-29T11:56:00.036653","level":"info","event":"‚¨áÔ∏è Descargando temperature_2m del Bucket S3 de AWS...","logger":"airflow.task.hooks.airflow.providers.standard.hooks.subprocess.SubprocessHook"}
{"timestamp":"2025-10-29T11:56:00.036962","level":"info","event":"‚¨áÔ∏è Descargando precipitation del Bucket S3 de AWS...","logger":"airflow.task.hooks.airflow.providers.standard.hooks.subprocess.SubprocessHook"}
{"timestamp":"2025-10-29T11:56:00.037255","level":"info","event":"‚¨áÔ∏è Descargando relative_humidity_2m del Bucket S3 de AWS...","logger":"airflow.task.hooks.airflow.providers.standard.hooks.subprocess.SubprocessHook"}
{"timestamp":"2025-10-29T11:56:00.037586","level":"info","event":"‚¨áÔ∏è Descargando shortwave_radiation del Bucket S3 de AWS...","logger":"airflow.task.hooks.airflow.providers.standard.hooks.subprocess.SubprocessHook"}
{"timestamp":"2025-10-29T11:56:00.037913","level":"info","event":"HTTPConnectionPool(host='host.docker.internal', port=8081): Max retries exceeded with url: /v1/forecast?latitude=39.1281556&longitude=-1.5212770999999998&models=meteofrance_arpege_europe&hourly=temperature_2m (Caused by NewConnectionError('<urllib3.connection.HTTPConnection object at 0x77f1b4bb5c40>: Failed to establish a new connection: [Errno 111] Connection refused'))","logger":"airflow.task.hooks.airflow.providers.standard.hooks.subprocess.SubprocessHook"}
{"timestamp":"2025-10-29T11:56:00.038198","level":"info","event":"HTTPConnectionPool(host='host.docker.internal', port=8081): Max retries exceeded with url: /v1/forecast?latitude=39.1281556&longitude=-1.5212770999999998&models=meteofrance_arpege_europe&hourly=precipitation (Caused by NewConnectionError('<urllib3.connection.HTTPConnection object at 0x77f1a75cce60>: Failed to establish a new connection: [Errno 111] Connection refused'))","logger":"airflow.task.hooks.airflow.providers.standard.hooks.subprocess.SubprocessHook"}
{"timestamp":"2025-10-29T11:56:00.038788","level":"info","event":"HTTPConnectionPool(host='host.docker.internal', port=8081): Max retries exceeded with url: /v1/forecast?latitude=39.1281556&longitude=-1.5212770999999998&models=meteofrance_arpege_europe&hourly=relative_humidity_2m (Caused by NewConnectionError('<urllib3.connection.HTTPConnection object at 0x77f1a75cd670>: Failed to establish a new connection: [Errno 111] Connection refused'))","logger":"airflow.task.hooks.airflow.providers.standard.hooks.subprocess.SubprocessHook"}
{"timestamp":"2025-10-29T11:56:00.039413","level":"info","event":"HTTPConnectionPool(host='host.docker.internal', port=8081): Max retries exceeded with url: /v1/forecast?latitude=39.1281556&longitude=-1.5212770999999998&models=meteofrance_arpege_europe&hourly=shortwave_radiation (Caused by NewConnectionError('<urllib3.connection.HTTPConnection object at 0x77f1a75cde80>: Failed to establish a new connection: [Errno 111] Connection refused'))","logger":"airflow.task.hooks.airflow.providers.standard.hooks.subprocess.SubprocessHook"}
{"timestamp":"2025-10-29T11:56:00.040518","level":"info","event":"HTTPConnectionPool(host='host.docker.internal', port=8081): Max retries exceeded with url: /v1/forecast?latitude=39.1281556&longitude=-0.5212770999999998&models=meteofrance_arpege_europe&hourly=temperature_2m (Caused by NewConnectionError('<urllib3.connection.HTTPConnection object at 0x77f1a75ce660>: Failed to establish a new connection: [Errno 111] Connection refused'))","logger":"airflow.task.hooks.airflow.providers.standard.hooks.subprocess.SubprocessHook"}
{"timestamp":"2025-10-29T11:56:00.040767","level":"info","event":"HTTPConnectionPool(host='host.docker.internal', port=8081): Max retries exceeded with url: /v1/forecast?latitude=39.1281556&longitude=-0.5212770999999998&models=meteofrance_arpege_europe&hourly=precipitation (Caused by NewConnectionError('<urllib3.connection.HTTPConnection object at 0x77f1b4b6cb00>: Failed to establish a new connection: [Errno 111] Connection refused'))","logger":"airflow.task.hooks.airflow.providers.standard.hooks.subprocess.SubprocessHook"}
{"timestamp":"2025-10-29T11:56:00.041026","level":"info","event":"HTTPConnectionPool(host='host.docker.internal', port=8081): Max retries exceeded with url: /v1/forecast?latitude=39.1281556&longitude=-0.5212770999999998&models=meteofrance_arpege_europe&hourly=relative_humidity_2m (Caused by NewConnectionError('<urllib3.connection.HTTPConnection object at 0x77f1a75ce8d0>: Failed to establish a new connection: [Errno 111] Connection refused'))","logger":"airflow.task.hooks.airflow.providers.standard.hooks.subprocess.SubprocessHook"}
{"timestamp":"2025-10-29T11:56:00.041377","level":"info","event":"HTTPConnectionPool(host='host.docker.internal', port=8081): Max retries exceeded with url: /v1/forecast?latitude=39.1281556&longitude=-0.5212770999999998&models=meteofrance_arpege_europe&hourly=shortwave_radiation (Caused by NewConnectionError('<urllib3.connection.HTTPConnection object at 0x77f1a75cddc0>: Failed to establish a new connection: [Errno 111] Connection refused'))","logger":"airflow.task.hooks.airflow.providers.standard.hooks.subprocess.SubprocessHook"}
{"timestamp":"2025-10-29T11:56:00.041714","level":"info","event":"HTTPConnectionPool(host='host.docker.internal', port=8081): Max retries exceeded with url: /v1/forecast?latitude=39.1281556&longitude=-1.5212770999999998&models=meteofrance_arpege_europe&hourly=temperature_2m (Caused by NewConnectionError('<urllib3.connection.HTTPConnection object at 0x77f1a75cd2b0>: Failed to establish a new connection: [Errno 111] Connection refused'))","logger":"airflow.task.hooks.airflow.providers.standard.hooks.subprocess.SubprocessHook"}
{"timestamp":"2025-10-29T11:56:00.041973","level":"info","event":"HTTPConnectionPool(host='host.docker.internal', port=8081): Max retries exceeded with url: /v1/forecast?latitude=39.1281556&longitude=-1.5212770999999998&models=meteofrance_arpege_europe&hourly=precipitation (Caused by NewConnectionError('<urllib3.connection.HTTPConnection object at 0x77f1a75cee40>: Failed to establish a new connection: [Errno 111] Connection refused'))","logger":"airflow.task.hooks.airflow.providers.standard.hooks.subprocess.SubprocessHook"}
{"timestamp":"2025-10-29T11:56:00.042259","level":"info","event":"HTTPConnectionPool(host='host.docker.internal', port=8081): Max retries exceeded with url: /v1/forecast?latitude=39.1281556&longitude=-1.5212770999999998&models=meteofrance_arpege_europe&hourly=relative_humidity_2m (Caused by NewConnectionError('<urllib3.connection.HTTPConnection object at 0x77f1a75cf7d0>: Failed to establish a new connection: [Errno 111] Connection refused'))","logger":"airflow.task.hooks.airflow.providers.standard.hooks.subprocess.SubprocessHook"}
{"timestamp":"2025-10-29T11:56:00.042452","level":"info","event":"HTTPConnectionPool(host='host.docker.internal', port=8081): Max retries exceeded with url: /v1/forecast?latitude=39.1281556&longitude=-1.5212770999999998&models=meteofrance_arpege_europe&hourly=shortwave_radiation (Caused by NewConnectionError('<urllib3.connection.HTTPConnection object at 0x77f1adc80b60>: Failed to establish a new connection: [Errno 111] Connection refused'))","logger":"airflow.task.hooks.airflow.providers.standard.hooks.subprocess.SubprocessHook"}
{"timestamp":"2025-10-29T11:56:00.042620","level":"info","event":"HTTPConnectionPool(host='host.docker.internal', port=8081): Max retries exceeded with url: /v1/forecast?latitude=39.1281556&longitude=-0.5212770999999998&models=meteofrance_arpege_europe&hourly=temperature_2m (Caused by NewConnectionError('<urllib3.connection.HTTPConnection object at 0x77f1a75cf800>: Failed to establish a new connection: [Errno 111] Connection refused'))","logger":"airflow.task.hooks.airflow.providers.standard.hooks.subprocess.SubprocessHook"}
{"timestamp":"2025-10-29T11:56:00.042865","level":"info","event":"HTTPConnectionPool(host='host.docker.internal', port=8081): Max retries exceeded with url: /v1/forecast?latitude=39.1281556&longitude=-0.5212770999999998&models=meteofrance_arpege_europe&hourly=precipitation (Caused by NewConnectionError('<urllib3.connection.HTTPConnection object at 0x77f1a75ceea0>: Failed to establish a new connection: [Errno 111] Connection refused'))","logger":"airflow.task.hooks.airflow.providers.standard.hooks.subprocess.SubprocessHook"}
{"timestamp":"2025-10-29T11:56:00.043037","level":"info","event":"HTTPConnectionPool(host='host.docker.internal', port=8081): Max retries exceeded with url: /v1/forecast?latitude=39.1281556&longitude=-0.5212770999999998&models=meteofrance_arpege_europe&hourly=relative_humidity_2m (Caused by NewConnectionError('<urllib3.connection.HTTPConnection object at 0x77f1a75cd670>: Failed to establish a new connection: [Errno 111] Connection refused'))","logger":"airflow.task.hooks.airflow.providers.standard.hooks.subprocess.SubprocessHook"}
{"timestamp":"2025-10-29T11:56:00.043328","level":"info","event":"HTTPConnectionPool(host='host.docker.internal', port=8081): Max retries exceeded with url: /v1/forecast?latitude=39.1281556&longitude=-0.5212770999999998&models=meteofrance_arpege_europe&hourly=shortwave_radiation (Caused by NewConnectionError('<urllib3.connection.HTTPConnection object at 0x77f1a75cdf10>: Failed to establish a new connection: [Errno 111] Connection refused'))","logger":"airflow.task.hooks.airflow.providers.standard.hooks.subprocess.SubprocessHook"}
{"timestamp":"2025-10-29T11:56:00.043547","level":"info","event":"HTTPConnectionPool(host='host.docker.internal', port=8081): Max retries exceeded with url: /v1/forecast?latitude=39.1281556&longitude=-1.5212770999999998&models=meteofrance_arpege_europe&hourly=temperature_2m (Caused by NewConnectionError('<urllib3.connection.HTTPConnection object at 0x77f1a75cfd40>: Failed to establish a new connection: [Errno 111] Connection refused'))","logger":"airflow.task.hooks.airflow.providers.standard.hooks.subprocess.SubprocessHook"}
{"timestamp":"2025-10-29T11:56:00.043714","level":"info","event":"HTTPConnectionPool(host='host.docker.internal', port=8081): Max retries exceeded with url: /v1/forecast?latitude=39.1281556&longitude=-1.5212770999999998&models=meteofrance_arpege_europe&hourly=precipitation (Caused by NewConnectionError('<urllib3.connection.HTTPConnection object at 0x77f1acc92720>: Failed to establish a new connection: [Errno 111] Connection refused'))","logger":"airflow.task.hooks.airflow.providers.standard.hooks.subprocess.SubprocessHook"}
{"timestamp":"2025-10-29T11:56:00.043988","level":"info","event":"HTTPConnectionPool(host='host.docker.internal', port=8081): Max retries exceeded with url: /v1/forecast?latitude=39.1281556&longitude=-1.5212770999999998&models=meteofrance_arpege_europe&hourly=relative_humidity_2m (Caused by NewConnectionError('<urllib3.connection.HTTPConnection object at 0x77f1a75ce8a0>: Failed to establish a new connection: [Errno 111] Connection refused'))","logger":"airflow.task.hooks.airflow.providers.standard.hooks.subprocess.SubprocessHook"}
{"timestamp":"2025-10-29T11:56:00.044301","level":"info","event":"HTTPConnectionPool(host='host.docker.internal', port=8081): Max retries exceeded with url: /v1/forecast?latitude=39.1281556&longitude=-1.5212770999999998&models=meteofrance_arpege_europe&hourly=shortwave_radiation (Caused by NewConnectionError('<urllib3.connection.HTTPConnection object at 0x77f1a75cd820>: Failed to establish a new connection: [Errno 111] Connection refused'))","logger":"airflow.task.hooks.airflow.providers.standard.hooks.subprocess.SubprocessHook"}
{"timestamp":"2025-10-29T11:56:00.248588","level":"info","event":"HTTPConnectionPool(host='host.docker.internal', port=8081): Max retries exceeded with url: /v1/forecast?latitude=39.1281556&longitude=-0.5212770999999998&models=meteofrance_arpege_europe&hourly=temperature_2m (Caused by NewConnectionError('<urllib3.connection.HTTPConnection object at 0x77f1a75cecf0>: Failed to establish a new connection: [Errno 111] Connection refused'))","logger":"airflow.task.hooks.airflow.providers.standard.hooks.subprocess.SubprocessHook"}
{"timestamp":"2025-10-29T11:56:00.248908","level":"info","event":"HTTPConnectionPool(host='host.docker.internal', port=8081): Max retries exceeded with url: /v1/forecast?latitude=39.1281556&longitude=-0.5212770999999998&models=meteofrance_arpege_europe&hourly=precipitation (Caused by NewConnectionError('<urllib3.connection.HTTPConnection object at 0x77f1a75cf530>: Failed to establish a new connection: [Errno 111] Connection refused'))","logger":"airflow.task.hooks.airflow.providers.standard.hooks.subprocess.SubprocessHook"}
{"timestamp":"2025-10-29T11:56:00.249116","level":"info","event":"HTTPConnectionPool(host='host.docker.internal', port=8081): Max retries exceeded with url: /v1/forecast?latitude=39.1281556&longitude=-0.5212770999999998&models=meteofrance_arpege_europe&hourly=relative_humidity_2m (Caused by NewConnectionError('<urllib3.connection.HTTPConnection object at 0x77f1ae560bc0>: Failed to establish a new connection: [Errno 111] Connection refused'))","logger":"airflow.task.hooks.airflow.providers.standard.hooks.subprocess.SubprocessHook"}
{"timestamp":"2025-10-29T11:56:00.249296","level":"info","event":"HTTPConnectionPool(host='host.docker.internal', port=8081): Max retries exceeded with url: /v1/forecast?latitude=39.1281556&longitude=-0.5212770999999998&models=meteofrance_arpege_europe&hourly=shortwave_radiation (Caused by NewConnectionError('<urllib3.connection.HTTPConnection object at 0x77f1a75d0650>: Failed to establish a new connection: [Errno 111] Connection refused'))","logger":"airflow.task.hooks.airflow.providers.standard.hooks.subprocess.SubprocessHook"}
{"timestamp":"2025-10-29T11:56:00.249491","level":"info","event":"HTTPConnectionPool(host='host.docker.internal', port=8081): Max retries exceeded with url: /v1/forecast?latitude=39.1281556&longitude=-1.5212770999999998&models=meteofrance_arpege_europe&hourly=temperature_2m (Caused by NewConnectionError('<urllib3.connection.HTTPConnection object at 0x77f1a75cfce0>: Failed to establish a new connection: [Errno 111] Connection refused'))","logger":"airflow.task.hooks.airflow.providers.standard.hooks.subprocess.SubprocessHook"}
{"timestamp":"2025-10-29T11:56:00.249744","level":"info","event":"HTTPConnectionPool(host='host.docker.internal', port=8081): Max retries exceeded with url: /v1/forecast?latitude=39.1281556&longitude=-1.5212770999999998&models=meteofrance_arpege_europe&hourly=precipitation (Caused by NewConnectionError('<urllib3.connection.HTTPConnection object at 0x77f1a75ccf50>: Failed to establish a new connection: [Errno 111] Connection refused'))","logger":"airflow.task.hooks.airflow.providers.standard.hooks.subprocess.SubprocessHook"}
{"timestamp":"2025-10-29T11:56:00.249926","level":"info","event":"HTTPConnectionPool(host='host.docker.internal', port=8081): Max retries exceeded with url: /v1/forecast?latitude=39.1281556&longitude=-1.5212770999999998&models=meteofrance_arpege_europe&hourly=relative_humidity_2m (Caused by NewConnectionError('<urllib3.connection.HTTPConnection object at 0x77f1a75cd640>: Failed to establish a new connection: [Errno 111] Connection refused'))","logger":"airflow.task.hooks.airflow.providers.standard.hooks.subprocess.SubprocessHook"}
{"timestamp":"2025-10-29T11:56:00.250095","level":"info","event":"HTTPConnectionPool(host='host.docker.internal', port=8081): Max retries exceeded with url: /v1/forecast?latitude=39.1281556&longitude=-1.5212770999999998&models=meteofrance_arpege_europe&hourly=shortwave_radiation (Caused by NewConnectionError('<urllib3.connection.HTTPConnection object at 0x77f1a75ce3c0>: Failed to establish a new connection: [Errno 111] Connection refused'))","logger":"airflow.task.hooks.airflow.providers.standard.hooks.subprocess.SubprocessHook"}
{"timestamp":"2025-10-29T11:56:00.250259","level":"info","event":"HTTPConnectionPool(host='host.docker.internal', port=8081): Max retries exceeded with url: /v1/forecast?latitude=39.1281556&longitude=-0.5212770999999998&models=meteofrance_arpege_europe&hourly=temperature_2m (Caused by NewConnectionError('<urllib3.connection.HTTPConnection object at 0x77f1a75ce780>: Failed to establish a new connection: [Errno 111] Connection refused'))","logger":"airflow.task.hooks.airflow.providers.standard.hooks.subprocess.SubprocessHook"}
{"timestamp":"2025-10-29T11:56:00.250419","level":"info","event":"HTTPConnectionPool(host='host.docker.internal', port=8081): Max retries exceeded with url: /v1/forecast?latitude=39.1281556&longitude=-0.5212770999999998&models=meteofrance_arpege_europe&hourly=precipitation (Caused by NewConnectionError('<urllib3.connection.HTTPConnection object at 0x77f1a75d0170>: Failed to establish a new connection: [Errno 111] Connection refused'))","logger":"airflow.task.hooks.airflow.providers.standard.hooks.subprocess.SubprocessHook"}
{"timestamp":"2025-10-29T11:56:00.250636","level":"info","event":"HTTPConnectionPool(host='host.docker.internal', port=8081): Max retries exceeded with url: /v1/forecast?latitude=39.1281556&longitude=-0.5212770999999998&models=meteofrance_arpege_europe&hourly=relative_humidity_2m (Caused by NewConnectionError('<urllib3.connection.HTTPConnection object at 0x77f1a75ce8d0>: Failed to establish a new connection: [Errno 111] Connection refused'))","logger":"airflow.task.hooks.airflow.providers.standard.hooks.subprocess.SubprocessHook"}
{"timestamp":"2025-10-29T11:56:00.250834","level":"info","event":"HTTPConnectionPool(host='host.docker.internal', port=8081): Max retries exceeded with url: /v1/forecast?latitude=39.1281556&longitude=-0.5212770999999998&models=meteofrance_arpege_europe&hourly=shortwave_radiation (Caused by NewConnectionError('<urllib3.connection.HTTPConnection object at 0x77f1a75cdc10>: Failed to establish a new connection: [Errno 111] Connection refused'))","logger":"airflow.task.hooks.airflow.providers.standard.hooks.subprocess.SubprocessHook"}
{"timestamp":"2025-10-29T11:56:00.250998","level":"info","event":"HTTPConnectionPool(host='host.docker.internal', port=8081): Max retries exceeded with url: /v1/forecast?latitude=40.1281556&longitude=-1.5212770999999998&models=meteofrance_arpege_europe&hourly=temperature_2m (Caused by NewConnectionError('<urllib3.connection.HTTPConnection object at 0x77f1a75cd460>: Failed to establish a new connection: [Errno 111] Connection refused'))","logger":"airflow.task.hooks.airflow.providers.standard.hooks.subprocess.SubprocessHook"}
{"timestamp":"2025-10-29T11:56:00.251187","level":"info","event":"HTTPConnectionPool(host='host.docker.internal', port=8081): Max retries exceeded with url: /v1/forecast?latitude=40.1281556&longitude=-1.5212770999999998&models=meteofrance_arpege_europe&hourly=precipitation (Caused by NewConnectionError('<urllib3.connection.HTTPConnection object at 0x77f1a75cf080>: Failed to establish a new connection: [Errno 111] Connection refused'))","logger":"airflow.task.hooks.airflow.providers.standard.hooks.subprocess.SubprocessHook"}
{"timestamp":"2025-10-29T11:56:00.251354","level":"info","event":"HTTPConnectionPool(host='host.docker.internal', port=8081): Max retries exceeded with url: /v1/forecast?latitude=40.1281556&longitude=-1.5212770999999998&models=meteofrance_arpege_europe&hourly=relative_humidity_2m (Caused by NewConnectionError('<urllib3.connection.HTTPConnection object at 0x77f1a75cdd00>: Failed to establish a new connection: [Errno 111] Connection refused'))","logger":"airflow.task.hooks.airflow.providers.standard.hooks.subprocess.SubprocessHook"}
{"timestamp":"2025-10-29T11:56:00.251559","level":"info","event":"HTTPConnectionPool(host='host.docker.internal', port=8081): Max retries exceeded with url: /v1/forecast?latitude=40.1281556&longitude=-1.5212770999999998&models=meteofrance_arpege_europe&hourly=shortwave_radiation (Caused by NewConnectionError('<urllib3.connection.HTTPConnection object at 0x77f1a75d0740>: Failed to establish a new connection: [Errno 111] Connection refused'))","logger":"airflow.task.hooks.airflow.providers.standard.hooks.subprocess.SubprocessHook"}
{"timestamp":"2025-10-29T11:56:00.251740","level":"info","event":"HTTPConnectionPool(host='host.docker.internal', port=8081): Max retries exceeded with url: /v1/forecast?latitude=40.1281556&longitude=-0.5212770999999998&models=meteofrance_arpege_europe&hourly=temperature_2m (Caused by NewConnectionError('<urllib3.connection.HTTPConnection object at 0x77f1a75cf860>: Failed to establish a new connection: [Errno 111] Connection refused'))","logger":"airflow.task.hooks.airflow.providers.standard.hooks.subprocess.SubprocessHook"}
{"timestamp":"2025-10-29T11:56:00.251907","level":"info","event":"HTTPConnectionPool(host='host.docker.internal', port=8081): Max retries exceeded with url: /v1/forecast?latitude=40.1281556&longitude=-0.5212770999999998&models=meteofrance_arpege_europe&hourly=precipitation (Caused by NewConnectionError('<urllib3.connection.HTTPConnection object at 0x77f1a75cedb0>: Failed to establish a new connection: [Errno 111] Connection refused'))","logger":"airflow.task.hooks.airflow.providers.standard.hooks.subprocess.SubprocessHook"}
{"timestamp":"2025-10-29T11:56:00.252070","level":"info","event":"HTTPConnectionPool(host='host.docker.internal', port=8081): Max retries exceeded with url: /v1/forecast?latitude=40.1281556&longitude=-0.5212770999999998&models=meteofrance_arpege_europe&hourly=relative_humidity_2m (Caused by NewConnectionError('<urllib3.connection.HTTPConnection object at 0x77f1a75ce1b0>: Failed to establish a new connection: [Errno 111] Connection refused'))","logger":"airflow.task.hooks.airflow.providers.standard.hooks.subprocess.SubprocessHook"}
{"timestamp":"2025-10-29T11:56:00.252230","level":"info","event":"HTTPConnectionPool(host='host.docker.internal', port=8081): Max retries exceeded with url: /v1/forecast?latitude=40.1281556&longitude=-0.5212770999999998&models=meteofrance_arpege_europe&hourly=shortwave_radiation (Caused by NewConnectionError('<urllib3.connection.HTTPConnection object at 0x77f1a75ceb70>: Failed to establish a new connection: [Errno 111] Connection refused'))","logger":"airflow.task.hooks.airflow.providers.standard.hooks.subprocess.SubprocessHook"}
{"timestamp":"2025-10-29T11:56:00.252385","level":"info","event":"HTTPConnectionPool(host='host.docker.internal', port=8081): Max retries exceeded with url: /v1/forecast?latitude=40.1281556&longitude=-1.5212770999999998&models=meteofrance_arpege_europe&hourly=temperature_2m (Caused by NewConnectionError('<urllib3.connection.HTTPConnection object at 0x77f1a75d09b0>: Failed to establish a new connection: [Errno 111] Connection refused'))","logger":"airflow.task.hooks.airflow.providers.standard.hooks.subprocess.SubprocessHook"}
{"timestamp":"2025-10-29T11:56:00.252594","level":"info","event":"HTTPConnectionPool(host='host.docker.internal', port=8081): Max retries exceeded with url: /v1/forecast?latitude=40.1281556&longitude=-1.5212770999999998&models=meteofrance_arpege_europe&hourly=precipitation (Caused by NewConnectionError('<urllib3.connection.HTTPConnection object at 0x77f1a75d1310>: Failed to establish a new connection: [Errno 111] Connection refused'))","logger":"airflow.task.hooks.airflow.providers.standard.hooks.subprocess.SubprocessHook"}
{"timestamp":"2025-10-29T11:56:00.511534","level":"info","event":"HTTPConnectionPool(host='host.docker.internal', port=8081): Max retries exceeded with url: /v1/forecast?latitude=40.1281556&longitude=-1.5212770999999998&models=meteofrance_arpege_europe&hourly=relative_humidity_2m (Caused by NewConnectionError('<urllib3.connection.HTTPConnection object at 0x77f1a75ce240>: Failed to establish a new connection: [Errno 111] Connection refused'))","logger":"airflow.task.hooks.airflow.providers.standard.hooks.subprocess.SubprocessHook"}
{"timestamp":"2025-10-29T11:56:00.511852","level":"info","event":"HTTPConnectionPool(host='host.docker.internal', port=8081): Max retries exceeded with url: /v1/forecast?latitude=40.1281556&longitude=-1.5212770999999998&models=meteofrance_arpege_europe&hourly=shortwave_radiation (Caused by NewConnectionError('<urllib3.connection.HTTPConnection object at 0x77f1a75ceff0>: Failed to establish a new connection: [Errno 111] Connection refused'))","logger":"airflow.task.hooks.airflow.providers.standard.hooks.subprocess.SubprocessHook"}
{"timestamp":"2025-10-29T11:56:00.512003","level":"info","event":"HTTPConnectionPool(host='host.docker.internal', port=8081): Max retries exceeded with url: /v1/forecast?latitude=40.1281556&longitude=-0.5212770999999998&models=meteofrance_arpege_europe&hourly=temperature_2m (Caused by NewConnectionError('<urllib3.connection.HTTPConnection object at 0x77f1a75cf260>: Failed to establish a new connection: [Errno 111] Connection refused'))","logger":"airflow.task.hooks.airflow.providers.standard.hooks.subprocess.SubprocessHook"}
{"timestamp":"2025-10-29T11:56:00.512264","level":"info","event":"HTTPConnectionPool(host='host.docker.internal', port=8081): Max retries exceeded with url: /v1/forecast?latitude=40.1281556&longitude=-0.5212770999999998&models=meteofrance_arpege_europe&hourly=precipitation (Caused by NewConnectionError('<urllib3.connection.HTTPConnection object at 0x77f1a75cdd00>: Failed to establish a new connection: [Errno 111] Connection refused'))","logger":"airflow.task.hooks.airflow.providers.standard.hooks.subprocess.SubprocessHook"}
{"timestamp":"2025-10-29T11:56:00.512507","level":"info","event":"HTTPConnectionPool(host='host.docker.internal', port=8081): Max retries exceeded with url: /v1/forecast?latitude=40.1281556&longitude=-0.5212770999999998&models=meteofrance_arpege_europe&hourly=relative_humidity_2m (Caused by NewConnectionError('<urllib3.connection.HTTPConnection object at 0x77f1a75d0980>: Failed to establish a new connection: [Errno 111] Connection refused'))","logger":"airflow.task.hooks.airflow.providers.standard.hooks.subprocess.SubprocessHook"}
{"timestamp":"2025-10-29T11:56:00.512633","level":"info","event":"HTTPConnectionPool(host='host.docker.internal', port=8081): Max retries exceeded with url: /v1/forecast?latitude=40.1281556&longitude=-0.5212770999999998&models=meteofrance_arpege_europe&hourly=shortwave_radiation (Caused by NewConnectionError('<urllib3.connection.HTTPConnection object at 0x77f1a75d1c40>: Failed to establish a new connection: [Errno 111] Connection refused'))","logger":"airflow.task.hooks.airflow.providers.standard.hooks.subprocess.SubprocessHook"}
{"timestamp":"2025-10-29T11:56:00.512749","level":"info","event":"HTTPConnectionPool(host='host.docker.internal', port=8081): Max retries exceeded with url: /v1/forecast?latitude=40.1281556&longitude=-1.5212770999999998&models=meteofrance_arpege_europe&hourly=temperature_2m (Caused by NewConnectionError('<urllib3.connection.HTTPConnection object at 0x77f1a75ceea0>: Failed to establish a new connection: [Errno 111] Connection refused'))","logger":"airflow.task.hooks.airflow.providers.standard.hooks.subprocess.SubprocessHook"}
{"timestamp":"2025-10-29T11:56:00.512862","level":"info","event":"HTTPConnectionPool(host='host.docker.internal', port=8081): Max retries exceeded with url: /v1/forecast?latitude=40.1281556&longitude=-1.5212770999999998&models=meteofrance_arpege_europe&hourly=precipitation (Caused by NewConnectionError('<urllib3.connection.HTTPConnection object at 0x77f1a75cd370>: Failed to establish a new connection: [Errno 111] Connection refused'))","logger":"airflow.task.hooks.airflow.providers.standard.hooks.subprocess.SubprocessHook"}
{"timestamp":"2025-10-29T11:56:00.513068","level":"info","event":"HTTPConnectionPool(host='host.docker.internal', port=8081): Max retries exceeded with url: /v1/forecast?latitude=40.1281556&longitude=-1.5212770999999998&models=meteofrance_arpege_europe&hourly=relative_humidity_2m (Caused by NewConnectionError('<urllib3.connection.HTTPConnection object at 0x77f1a75ce060>: Failed to establish a new connection: [Errno 111] Connection refused'))","logger":"airflow.task.hooks.airflow.providers.standard.hooks.subprocess.SubprocessHook"}
{"timestamp":"2025-10-29T11:56:00.513188","level":"info","event":"HTTPConnectionPool(host='host.docker.internal', port=8081): Max retries exceeded with url: /v1/forecast?latitude=40.1281556&longitude=-1.5212770999999998&models=meteofrance_arpege_europe&hourly=shortwave_radiation (Caused by NewConnectionError('<urllib3.connection.HTTPConnection object at 0x77f1a75ceb40>: Failed to establish a new connection: [Errno 111] Connection refused'))","logger":"airflow.task.hooks.airflow.providers.standard.hooks.subprocess.SubprocessHook"}
{"timestamp":"2025-10-29T11:56:00.513298","level":"info","event":"HTTPConnectionPool(host='host.docker.internal', port=8081): Max retries exceeded with url: /v1/forecast?latitude=40.1281556&longitude=-0.5212770999999998&models=meteofrance_arpege_europe&hourly=temperature_2m (Caused by NewConnectionError('<urllib3.connection.HTTPConnection object at 0x77f1a75d1df0>: Failed to establish a new connection: [Errno 111] Connection refused'))","logger":"airflow.task.hooks.airflow.providers.standard.hooks.subprocess.SubprocessHook"}
{"timestamp":"2025-10-29T11:56:00.513420","level":"info","event":"HTTPConnectionPool(host='host.docker.internal', port=8081): Max retries exceeded with url: /v1/forecast?latitude=40.1281556&longitude=-0.5212770999999998&models=meteofrance_arpege_europe&hourly=precipitation (Caused by NewConnectionError('<urllib3.connection.HTTPConnection object at 0x77f1a75d1460>: Failed to establish a new connection: [Errno 111] Connection refused'))","logger":"airflow.task.hooks.airflow.providers.standard.hooks.subprocess.SubprocessHook"}
{"timestamp":"2025-10-29T11:56:00.513684","level":"info","event":"HTTPConnectionPool(host='host.docker.internal', port=8081): Max retries exceeded with url: /v1/forecast?latitude=40.1281556&longitude=-0.5212770999999998&models=meteofrance_arpege_europe&hourly=relative_humidity_2m (Caused by NewConnectionError('<urllib3.connection.HTTPConnection object at 0x77f1a75cde20>: Failed to establish a new connection: [Errno 111] Connection refused'))","logger":"airflow.task.hooks.airflow.providers.standard.hooks.subprocess.SubprocessHook"}
{"timestamp":"2025-10-29T11:56:00.513845","level":"info","event":"HTTPConnectionPool(host='host.docker.internal', port=8081): Max retries exceeded with url: /v1/forecast?latitude=40.1281556&longitude=-0.5212770999999998&models=meteofrance_arpege_europe&hourly=shortwave_radiation (Caused by NewConnectionError('<urllib3.connection.HTTPConnection object at 0x77f1a75cd0a0>: Failed to establish a new connection: [Errno 111] Connection refused'))","logger":"airflow.task.hooks.airflow.providers.standard.hooks.subprocess.SubprocessHook"}
{"timestamp":"2025-10-29T11:56:00.513960","level":"info","event":"HTTPConnectionPool(host='host.docker.internal', port=8081): Max retries exceeded with url: /v1/forecast?latitude=40.1281556&longitude=-1.5212770999999998&models=meteofrance_arpege_europe&hourly=temperature_2m (Caused by NewConnectionError('<urllib3.connection.HTTPConnection object at 0x77f1a75cf560>: Failed to establish a new connection: [Errno 111] Connection refused'))","logger":"airflow.task.hooks.airflow.providers.standard.hooks.subprocess.SubprocessHook"}
{"timestamp":"2025-10-29T11:56:00.514155","level":"info","event":"HTTPConnectionPool(host='host.docker.internal', port=8081): Max retries exceeded with url: /v1/forecast?latitude=40.1281556&longitude=-1.5212770999999998&models=meteofrance_arpege_europe&hourly=precipitation (Caused by NewConnectionError('<urllib3.connection.HTTPConnection object at 0x77f1a75cd910>: Failed to establish a new connection: [Errno 111] Connection refused'))","logger":"airflow.task.hooks.airflow.providers.standard.hooks.subprocess.SubprocessHook"}
{"timestamp":"2025-10-29T11:56:00.514283","level":"info","event":"HTTPConnectionPool(host='host.docker.internal', port=8081): Max retries exceeded with url: /v1/forecast?latitude=40.1281556&longitude=-1.5212770999999998&models=meteofrance_arpege_europe&hourly=relative_humidity_2m (Caused by NewConnectionError('<urllib3.connection.HTTPConnection object at 0x77f1a75cfcb0>: Failed to establish a new connection: [Errno 111] Connection refused'))","logger":"airflow.task.hooks.airflow.providers.standard.hooks.subprocess.SubprocessHook"}
{"timestamp":"2025-10-29T11:56:00.514396","level":"info","event":"HTTPConnectionPool(host='host.docker.internal', port=8081): Max retries exceeded with url: /v1/forecast?latitude=40.1281556&longitude=-1.5212770999999998&models=meteofrance_arpege_europe&hourly=shortwave_radiation (Caused by NewConnectionError('<urllib3.connection.HTTPConnection object at 0x77f1a75d1f70>: Failed to establish a new connection: [Errno 111] Connection refused'))","logger":"airflow.task.hooks.airflow.providers.standard.hooks.subprocess.SubprocessHook"}
{"timestamp":"2025-10-29T11:56:00.514506","level":"info","event":"HTTPConnectionPool(host='host.docker.internal', port=8081): Max retries exceeded with url: /v1/forecast?latitude=40.1281556&longitude=-0.5212770999999998&models=meteofrance_arpege_europe&hourly=temperature_2m (Caused by NewConnectionError('<urllib3.connection.HTTPConnection object at 0x77f1a75cfb00>: Failed to establish a new connection: [Errno 111] Connection refused'))","logger":"airflow.task.hooks.airflow.providers.standard.hooks.subprocess.SubprocessHook"}
{"timestamp":"2025-10-29T11:56:00.514693","level":"info","event":"HTTPConnectionPool(host='host.docker.internal', port=8081): Max retries exceeded with url: /v1/forecast?latitude=40.1281556&longitude=-0.5212770999999998&models=meteofrance_arpege_europe&hourly=precipitation (Caused by NewConnectionError('<urllib3.connection.HTTPConnection object at 0x77f1a75cf740>: Failed to establish a new connection: [Errno 111] Connection refused'))","logger":"airflow.task.hooks.airflow.providers.standard.hooks.subprocess.SubprocessHook"}
{"timestamp":"2025-10-29T11:56:00.514828","level":"info","event":"HTTPConnectionPool(host='host.docker.internal', port=8081): Max retries exceeded with url: /v1/forecast?latitude=40.1281556&longitude=-0.5212770999999998&models=meteofrance_arpege_europe&hourly=relative_humidity_2m (Caused by NewConnectionError('<urllib3.connection.HTTPConnection object at 0x77f1a75ce240>: Failed to establish a new connection: [Errno 111] Connection refused'))","logger":"airflow.task.hooks.airflow.providers.standard.hooks.subprocess.SubprocessHook"}
{"timestamp":"2025-10-29T11:56:00.514943","level":"info","event":"HTTPConnectionPool(host='host.docker.internal', port=8081): Max retries exceeded with url: /v1/forecast?latitude=40.1281556&longitude=-0.5212770999999998&models=meteofrance_arpege_europe&hourly=shortwave_radiation (Caused by NewConnectionError('<urllib3.connection.HTTPConnection object at 0x77f1a75cef60>: Failed to establish a new connection: [Errno 111] Connection refused'))","logger":"airflow.task.hooks.airflow.providers.standard.hooks.subprocess.SubprocessHook"}
{"timestamp":"2025-10-29T11:56:00.515054","level":"info","event":"","logger":"airflow.task.hooks.airflow.providers.standard.hooks.subprocess.SubprocessHook"}
{"timestamp":"2025-10-29T11:56:00.515215","level":"info","event":"üèÅ Descarga completada en 12.13 s (0.20 min)","logger":"airflow.task.hooks.airflow.providers.standard.hooks.subprocess.SubprocessHook"}
{"timestamp":"2025-10-29T11:56:00.515414","level":"info","event":"‚ùå No se obtuvieron datos.","logger":"airflow.task.hooks.airflow.providers.standard.hooks.subprocess.SubprocessHook"}
{"timestamp":"2025-10-29T11:56:00.515541","level":"info","event":"Traceback (most recent call last):","logger":"airflow.task.hooks.airflow.providers.standard.hooks.subprocess.SubprocessHook"}
{"timestamp":"2025-10-29T11:56:00.515651","level":"info","event":"  File \"/opt/airflow/scripts/ARPEGE.py\", line 177, in <module>","logger":"airflow.task.hooks.airflow.providers.standard.hooks.subprocess.SubprocessHook"}
{"timestamp":"2025-10-29T11:56:00.515834","level":"info","event":"    main()","logger":"airflow.task.hooks.airflow.providers.standard.hooks.subprocess.SubprocessHook"}
{"timestamp":"2025-10-29T11:56:00.515979","level":"info","event":"  File \"/opt/airflow/scripts/ARPEGE.py\", line 157, in main","logger":"airflow.task.hooks.airflow.providers.standard.hooks.subprocess.SubprocessHook"}
{"timestamp":"2025-10-29T11:56:00.516108","level":"info","event":"    df = df.dropna(subset=VARIABLES) # Borra las filas con datos de las variables faltantes que corresponden a predicciones no disponibles.","logger":"airflow.task.hooks.airflow.providers.standard.hooks.subprocess.SubprocessHook"}
{"timestamp":"2025-10-29T11:56:00.516221","level":"info","event":"         ^^^^^^^^^^^^^^^^^^^^^^^^^^^","logger":"airflow.task.hooks.airflow.providers.standard.hooks.subprocess.SubprocessHook"}
{"timestamp":"2025-10-29T11:56:00.516328","level":"info","event":"  File \"/home/airflow/.local/lib/python3.12/site-packages/pandas/core/frame.py\", line 6418, in dropna","logger":"airflow.task.hooks.airflow.providers.standard.hooks.subprocess.SubprocessHook"}
{"timestamp":"2025-10-29T11:56:00.516791","level":"info","event":"    raise KeyError(np.array(subset)[check].tolist())","logger":"airflow.task.hooks.airflow.providers.standard.hooks.subprocess.SubprocessHook"}
{"timestamp":"2025-10-29T11:56:00.517037","level":"info","event":"KeyError: ['temperature_2m', 'precipitation', 'relative_humidity_2m', 'shortwave_radiation']","logger":"airflow.task.hooks.airflow.providers.standard.hooks.subprocess.SubprocessHook"}
{"timestamp":"2025-10-29T11:56:00.769588","level":"info","event":"Command exited with return code 1","logger":"airflow.task.hooks.airflow.providers.standard.hooks.subprocess.SubprocessHook"}
{"timestamp":"2025-10-29T11:56:00.771328","level":"error","event":"Task failed with exception","logger":"task","error_detail":[{"exc_type":"AirflowException","exc_value":"Bash command failed. The command returned a non-zero exit code 1.","exc_notes":[],"syntax_error":null,"is_cause":false,"frames":[{"filename":"/home/airflow/.local/lib/python3.12/site-packages/airflow/sdk/execution_time/task_runner.py","lineno":920,"name":"run"},{"filename":"/home/airflow/.local/lib/python3.12/site-packages/airflow/sdk/execution_time/task_runner.py","lineno":1215,"name":"_execute_task"},{"filename":"/home/airflow/.local/lib/python3.12/site-packages/airflow/sdk/bases/operator.py","lineno":397,"name":"wrapper"},{"filename":"/home/airflow/.local/lib/python3.12/site-packages/airflow/providers/standard/operators/bash.py","lineno":232,"name":"execute"}],"is_group":false,"exceptions":[]}]}
